Workbook

Sheet PriceList
A1: Duraforge Price List | M1: FPE SEALS | Grey Background | Z1: ANALYSIS
A2: Exchange Rate Used: £1 = ₹122.5 | Source: 6-month average Oct 2025–Apr 2026 | Positive 'Price Diff ₹' = FPE costs MORE than your price
A3: PR Code | B3: Name / Part Code | C3: Seal Type | D3: Series | E3: Material | F3: Inner Ø (mm) | G3: Outer Ø (mm) | H3: Depth (mm) | I3: Price ₹ (INR) | J3: PO Price ££ | K3: Landing Price ££ | L3: Advertised Price ££ | M3: SKU | N3: Description | O3: Category | P3: Product Type | Q3: Inner Ø (mm) | R3: Outer Ø (mm) | S3: Depth (mm) | T3: Price £ (GBP) | U3: Diff | V3: GBP→INR (₹) | W3: Price ₹ (INR) | X3: Stock Qty | Y3: Dim Source | Z3: Price Diff ₹ | AA3: Diff % | AB3: Match Note
A4: 108683 | B4: DS011-F-0120-0180-03.8/5 | C4: Dust Seal | D4: 011 | E4: Standard (NBR/PU) | F4: 12 | G4: 18 | H4: 3.8-5.0 | I4: 44 | J4: =I4*0.0087 -> 0.3828 | K4: =ROUND(J4*1.5,2) -> 0.57 | L4: =K4*4 -> 2.28 | M4: WR12-18-4-7UL-P-H839 | N4: The Hallite 839 double-lipped, snap-in wiper is designed to fit standard housings, including many ISO 6195C sizes, and to exclude dirt and moisture from entering the cylinder. The design minimises the oil transfer out of the ram on the cylinder rod by collecting traces of fluid passing the rod seal.Opposite the wiper lip are two sealing lips that are precision trimmed at an angle to give optimal rod sealing performance. The Hallite 839 is designed to have an interference in the seal housing groove to improve the stability of the wiper in the gland and to reduce the possibility of ingress around the outside of the wiper.Hallite recommends a vent is provided between the seal and the wiper to avoid a pressure trap. For customers that require a wiper for heavier duty applications, the Hallite technical team may advise you to use a Hallite 844 wiper instead of the Hallite 839. Contact your local Hallite team for more information. | O4: Hallite Wiper Seal | P4: HalliteÂ® Type 839 | Q4: 12 | R4: 18 | S4: 4 | T4: 4.28 | U4: =T4-L4 -> 2 | V4: 524.3 | W4: 524.3 | X4: 20 | Y4: mm | Z4: 480.3 | AA4: 1091.6 | AB4: ID diff=0.00mm, OD diff=0.00mm
A5: 108686 | B5: DS011-F-0180-0240-03.8/5 | C5: Dust Seal | D5: 011 | E5: Standard (NBR/PU) | F5: 18 | G5: 24 | H5: 3.8-5.0 | I5: 47 | J5: =I5*0.0087 -> 0.4089 | K5: =ROUND(J5*1.5,2) -> 0.61 | L5: =K5*4 -> 2.44 | M5: WR18-24-5-7M-P-H38 | N5: The Hallite 38 single-lipped wiper/scraper is designed to fit metric housingsÂ including those of ISO 6195A. The proportions of the wiping lip ensure that contactÂ is maintained with the surface of the rod to remove heavily deposited containments such as mud and ice. The outside diameter of the wiper incorporates a crush lip to provide an interference fit with the housing. This feature help prevent contamination from entering the groove. The Hallite 38 is molded in a polyester-based material to provide a tough, abrasion_x0002_resistant wiper for the difficult conditions usually found in mining or earth moving applications. The complete range can be used with a split housing, and the majority can be installed in a blind housing with care | O5: Hallite Wiper Seal | P5: HalliteÂ® Type 38 | Q5: 18 | R5: 24 | S5: 5 | T5: 4.15 | U5: =T5-L5 -> 1.71 | V5: 508.38 | W5: 508.38 | X5: 127 | Y5: mm | Z5: 461.38 | AA5: 981.7 | AB5: ID diff=0.00mm, OD diff=0.00mm
A6: 110070 | B6: DS011-F-0180-0260-0507 | C6: Dust Seal | D6: 011 | E6: Standard (NBR/PU) | F6: 18 | G6: 26 | H6: 5.0-7.0 | I6: 59 | J6: =I6*0.0087 -> 0.5133 | K6: =ROUND(J6*1.5,2) -> 0.77 | L6: =K6*4 -> 3.08 | M6: WR18-26-4-6M-R-H33 | N6: The Hallite 33 wiper has a lip designed to remove lightly adhered dirt from the rod i.e. mud, dust or moisture.Â The wiper is manufactured from a hard nitrile rubber suitable for installing in a grooved housing. Rod diameters(Ã˜d1) of 20mm and below require a two piece housing .Â To prevent dirt passing the outside of the wiper and to reduce the pumping action, the outside diameter is anÂ interference fit with the housing. Certain sizes of the standard Hallite 33 metric range are suitable for ISO 6195Â Housing Type A.Â It should also be noted that the Hallite 33 inch profile differs from the metric profile | O6: Hallite Wiper Seal | P6: HalliteÂ® Type 33 | Q6: 18 | R6: 26 | S6: 4 | T6: 4.19 | U6: =T6-L6 -> 1.11 | V6: 513.28 | W6: 513.28 | X6: 55 | Y6: mm | Z6: 454.28 | AA6: 770 | AB6: ID diff=0.00mm, OD diff=0.00mm
A7: 108687 | B7: DS011-F-0200-0280-0507 | C7: Dust Seal | D7: 011 | E7: Standard (NBR/PU) | F7: 20 | G7: 28 | H7: 5.0-7.0 | I7: 62 | J7: =I7*0.0087 -> 0.5394 | K7: =ROUND(J7*1.5,2) -> 0.81 | L7: =K7*4 -> 3.24 | M7: WR20-28-4-6C-R-H33 | N7: The Hallite 33 wiper has a lip designed to remove lightly adhered dirt from the rod i.e. mud, dust or moisture.Â The wiper is manufactured from a hard nitrile rubber suitable for installing in a grooved housing. Rod diameters(Ã˜d1) of 20mm and below require a two piece housing .Â To prevent dirt passing the outside of the wiper and to reduce the pumping action, the outside diameter is anÂ interference fit with the housing. Certain sizes of the standard Hallite 33 metric range are suitable for ISO 6195Â Housing Type A.Â It should also be noted that the Hallite 33 inch profile differs from the metric profile | O7: Hallite Wiper Seal | P7: HalliteÂ® Type 33 | Q7: 20 | R7: 28 | S7: 4 | T7: 11.74 | U7: =T7-L7 -> 8.5 | V7: 1438.15 | W7: 1438.15 | X7: Get A Quote | Y7: mm | Z7: 1376.15 | AA7: 2219.6 | AB7: ID diff=0.00mm, OD diff=0.00mm
A8: 108688 | B8: DS011-F-0220-0300-0507 | C8: Dust Seal | D8: 011 | E8: Standard (NBR/PU) | F8: 22 | G8: 30 | H8: 5.0-7.0 | I8: 62 | J8: =I8*0.0087 -> 0.5394 | K8: =ROUND(J8*1.5,2) -> 0.81 | L8: =K8*4 -> 3.24 | M8: WR22-30-4-6M-R-H33 | N8: The Hallite 33 wiper has a lip designed to remove lightly adhered dirt from the rod i.e. mud, dust or moisture.Â The wiper is manufactured from a hard nitrile rubber suitable for installing in a grooved housing. Rod diameters(Ã˜d1) of 20mm and below require a two piece housing .Â To prevent dirt passing the outside of the wiper and to reduce the pumping action, the outside diameter is anÂ interference fit with the housing. Certain sizes of the standard Hallite 33 metric range are suitable for ISO 6195Â Housing Type A.Â It should also be noted that the Hallite 33 inch profile differs from the metric profile | O8: Hallite Wiper Seal | P8: HalliteÂ® Type 33 | Q8: 22 | R8: 30 | S8: 4 | T8: 7.14 | U8: =T8-L8 -> 3.9 | V8: 874.65 | W8: 874.65 | X8: 16 | Y8: mm | Z8: 812.65 | AA8: 1310.7 | AB8: ID diff=0.00mm, OD diff=0.00mm
A9: 108689 | B9: DS011-F-0250-0330-0507 | C9: Dust Seal | D9: 011 | E9: Standard (NBR/PU) | F9: 25 | G9: 33 | H9: 5.0-7.0 | I9: 66 | J9: =I9*0.0087 -> 0.5742 | K9: =ROUND(J9*1.5,2) -> 0.86 | L9: =K9*4 -> 3.44 | M9: WR25-33-4-6M-R-H33 | N9: The Hallite 33 wiper has a lip designed to remove lightly adhered dirt from the rod i.e. mud, dust or moisture.Â The wiper is manufactured from a hard nitrile rubber suitable for installing in a grooved housing. Rod diameters(Ã˜d1) of 20mm and below require a two piece housing .Â To prevent dirt passing the outside of the wiper and to reduce the pumping action, the outside diameter is anÂ interference fit with the housing. Certain sizes of the standard Hallite 33 metric range are suitable for ISO 6195Â Housing Type A.Â It should also be noted that the Hallite 33 inch profile differs from the metric profile | O9: Hallite Wiper Seal | P9: HalliteÂ® Type 33 | Q9: 25 | R9: 33 | S9: 4 | T9: 7.87 | U9: =T9-L9 -> 4.43 | V9: 964.08 | W9: 964.08 | X9: Get A Quote | Y9: mm | Z9: 898.08 | AA9: 1360.7 | AB9: ID diff=0.00mm, OD diff=0.00mm
A10: 108690 | B10: DS011-F-0280-0360-0507 | C10: Dust Seal | D10: 011 | E10: Standard (NBR/PU) | F10: 28 | G10: 36 | H10: 5.0-7.0 | I10: 76 | J10: =I10*0.0087 -> 0.6612 | K10: =ROUND(J10*1.5,2) -> 0.99 | L10: =K10*4 -> 3.96 | M10: WR28-36-5-7M-P-H38 | N10: The Hallite 38 single-lipped wiper/scraper is designed to fit metric housingsÂ including those of ISO 6195A. The proportions of the wiping lip ensure that contactÂ is maintained with the surface of the rod to remove heavily deposited containments such as mud and ice. The outside diameter of the wiper incorporates a crush lip to provide an interference fit with the housing. This feature help prevent contamination from entering the groove. The Hallite 38 is molded in a polyester-based material to provide a tough, abrasion_x0002_resistant wiper for the difficult conditions usually found in mining or earth moving applications. The complete range can be used with a split housing, and the majority can be installed in a blind housing with care | O10: Hallite Wiper Seal | P10: HalliteÂ® Type 38 | Q10: 28 | R10: 36 | S10: 5 | T10: 5.53 | U10: =T10-L10 -> 1.57 | V10: 677.42 | W10: 677.42 | X10: 381 | Y10: mm | Z10: 601.42 | AA10: 791.3 | AB10: ID diff=0.00mm, OD diff=0.00mm
A11: 108691 | B11: DS011-F-0300-0380-0507 | C11: Dust Seal | D11: 011 | E11: Standard (NBR/PU) | F11: 30 | G11: 38 | H11: 5.0-7.0 | I11: 76 | J11: =I11*0.0087 -> 0.6612 | K11: =ROUND(J11*1.5,2) -> 0.99 | L11: =K11*4 -> 3.96 | M11: WR30-38-5-7M-P-H38 | N11: The Hallite 38 single-lipped wiper/scraper is designed to fit metric housingsÂ including those of ISO 6195A. The proportions of the wiping lip ensure that contactÂ is maintained with the surface of the rod to remove heavily deposited containments such as mud and ice. The outside diameter of the wiper incorporates a crush lip to provide an interference fit with the housing. This feature help prevent contamination from entering the groove. The Hallite 38 is molded in a polyester-based material to provide a tough, abrasion_x0002_resistant wiper for the difficult conditions usually found in mining or earth moving applications. The complete range can be used with a split housing, and the majority can be installed in a blind housing with care | O11: Hallite Wiper Seal | P11: HalliteÂ® Type 38 | Q11: 30 | R11: 38 | S11: 5 | T11: 5.98 | U11: =T11-L11 -> 2.02 | V11: 732.55 | W11: 732.55 | X11: 138 | Y11: mm | Z11: 656.55 | AA11: 863.9 | AB11: ID diff=0.00mm, OD diff=0.00mm
A12: 108692 | B12: DS011-F-0320-0400-0507 | C12: Dust Seal | D12: 011 | E12: Standard (NBR/PU) | F12: 32 | G12: 40 | H12: 5.0-7.0 | I12: 79 | J12: =I12*0.0087 -> 0.6873 | K12: =ROUND(J12*1.5,2) -> 1.03 | L12: =K12*4 -> 4.12 | M12: WR32-40-5-6.4M-R-H33 | N12: The Hallite 33 wiper has a lip designed to remove lightly adhered dirt from the rod i.e. mud, dust or moisture.Â The wiper is manufactured from a hard nitrile rubber suitable for installing in a grooved housing. Rod diameters(Ã˜d1) of 20mm and below require a two piece housing .Â To prevent dirt passing the outside of the wiper and to reduce the pumping action, the outside diameter is anÂ interference fit with the housing. Certain sizes of the standard Hallite 33 metric range are suitable for ISO 6195Â Housing Type A.Â It should also be noted that the Hallite 33 inch profile differs from the metric profile | O12: Hallite Wiper Seal | P12: HalliteÂ® Type 33 | Q12: 32 | R12: 40 | S12: 5 | T12: 7.49 | U12: =T12-L12 -> 3.37 | V12: 917.52 | W12: 917.52 | X12: 11 | Y12: mm | Z12: 838.52 | AA12: 1061.4 | AB12: ID diff=0.00mm, OD diff=0.00mm
A13: 108693 | B13: DS011-F-0350-0430-0507 | C13: Dust Seal | D13: 011 | E13: Standard (NBR/PU) | F13: 35 | G13: 43 | H13: 5.0-7.0 | I13: 79 | J13: =I13*0.0087 -> 0.6873 | K13: =ROUND(J13*1.5,2) -> 1.03 | L13: =K13*4 -> 4.12 | M13: WR35-43-5-7M-P-H38 | N13: The Hallite 38 single-lipped wiper/scraper is designed to fit metric housingsÂ including those of ISO 6195A. The proportions of the wiping lip ensure that contactÂ is maintained with the surface of the rod to remove heavily deposited containments such as mud and ice. The outside diameter of the wiper incorporates a crush lip to provide an interference fit with the housing. This feature help prevent contamination from entering the groove. The Hallite 38 is molded in a polyester-based material to provide a tough, abrasion_x0002_resistant wiper for the difficult conditions usually found in mining or earth moving applications. The complete range can be used with a split housing, and the majority can be installed in a blind housing with care | O13: Hallite Wiper Seal | P13: HalliteÂ® Type 38 | Q13: 35 | R13: 43 | S13: 5 | T13: 6.64 | U13: =T13-L13 -> 2.52 | V13: 813.4 | W13: 813.4 | X13: 102 | Y13: mm | Z13: 734.4 | AA13: 929.6 | AB13: ID diff=0.00mm, OD diff=0.00mm
A14: 108694 | B14: DS011-F-0360-0440-0507 | C14: Dust Seal | D14: 011 | E14: Standard (NBR/PU) | F14: 36 | G14: 44 | H14: 5.0-7.0 | I14: 84 | J14: =I14*0.0087 -> 0.7308 | K14: =ROUND(J14*1.5,2) -> 1.1 | L14: =K14*4 -> 4.4 | M14: WR36-44-5-7M-P-H38 | N14: The Hallite 38 single-lipped wiper/scraper is designed to fit metric housingsÂ including those of ISO 6195A. The proportions of the wiping lip ensure that contactÂ is maintained with the surface of the rod to remove heavily deposited containments such as mud and ice. The outside diameter of the wiper incorporates a crush lip to provide an interference fit with the housing. This feature help prevent contamination from entering the groove. The Hallite 38 is molded in a polyester-based material to provide a tough, abrasion_x0002_resistant wiper for the difficult conditions usually found in mining or earth moving applications. The complete range can be used with a split housing, and the majority can be installed in a blind housing with care | O14: Hallite Wiper Seal | P14: HalliteÂ® Type 38 | Q14: 36 | R14: 44 | S14: 5 | T14: 6.87 | U14: =T14-L14 -> 2.47 | V14: 841.58 | W14: 841.58 | X14: 103 | Y14: mm | Z14: 757.58 | AA14: 901.9 | AB14: ID diff=0.00mm, OD diff=0.00mm
A15: 112557 | B15: DS011-F-0380-0460-0507 | C15: Dust Seal | D15: 011 | E15: Standard (NBR/PU) | F15: 38 | G15: 46 | H15: 5.0-7.0 | I15: 84 | J15: =I15*0.0087 -> 0.7308 | K15: =ROUND(J15*1.5,2) -> 1.1 | L15: =K15*4 -> 4.4 | M15: WR38-46-5-8A6-P-H842 | N15: The Hallite 842 single-lipped, snap-in rod wiper is developed specifically for use in harsher environments with heavy contamination, such as in agriculture, off-highway, forestry, and long wall mining equipment.The unique feature of the Hallite 842 is the Umbrella Wiper Technologyâ„¢, which is a protective debris guard flap on the wiping lip that entirely covers the gland housing and prevents the water/slurry trap that is common with conventional wipers. This feature offers added protection to the integrity of the hydraulic system, providing increased system life by reducing corrosion and preventing the ingress of contamination into the wiper housing groove and hydraulic cylinder gland.The moulded ribs on the internal diameter provide extra stability to the wiper and help prevent the possibility of blow-out due to pressure trapping between the wiper and the main rod seal. | O15: Hallite Wiper Seal | P15: HalliteÂ® Type 842 | Q15: 38 | R15: 46 | S15: 5 | T15: 20.05 | U15: =T15-L15 -> 15.65 | V15: 2456.12 | W15: 2456.12 | X15: 47 | Y15: mm | Z15: 2372.12 | AA15: 2824 | AB15: ID diff=0.00mm, OD diff=0.00mm
A16: 108695 | B16: DS011-F-0400-0480-0507 | C16: Dust Seal | D16: 011 | E16: Standard (NBR/PU) | F16: 40 | G16: 48 | H16: 5.0-7.0 | I16: 86 | J16: =I16*0.0087 -> 0.7482 | K16: =ROUND(J16*1.5,2) -> 1.12 | L16: =K16*4 -> 4.48 | M16: WR40-48-5-7M-P-H38 | N16: The Hallite 38 single-lipped wiper/scraper is designed to fit metric housingsÂ including those of ISO 6195A. The proportions of the wiping lip ensure that contactÂ is maintained with the surface of the rod to remove heavily deposited containments such as mud and ice. The outside diameter of the wiper incorporates a crush lip to provide an interference fit with the housing. This feature help prevent contamination from entering the groove. The Hallite 38 is molded in a polyester-based material to provide a tough, abrasion_x0002_resistant wiper for the difficult conditions usually found in mining or earth moving applications. The complete range can be used with a split housing, and the majority can be installed in a blind housing with care | O16: Hallite Wiper Seal | P16: HalliteÂ® Type 38 | Q16: 40 | R16: 48 | S16: 5 | T16: 6.87 | U16: =T16-L16 -> 2.39 | V16: 841.58 | W16: 841.58 | X16: 254 | Y16: mm | Z16: 755.58 | AA16: 878.6 | AB16: ID diff=0.00mm, OD diff=0.00mm
A17: 108696 | B17: DS011-F-0420-0500-0507 | C17: Dust Seal | D17: 011 | E17: Standard (NBR/PU) | F17: 42 | G17: 50 | H17: 5.0-7.0 | I17: 86 | J17: =I17*0.0087 -> 0.7482 | K17: =ROUND(J17*1.5,2) -> 1.12 | L17: =K17*4 -> 4.48 | M17: WR162200-018-028M-XL-P-H520 | N17: The Hallite 520 single-lipped, snap-in rod wiper is designed to fitÂ D-style housings. The proportions of the wiping lip ensure that contact isÂ maintained with the surface of the rod to remove heavily deposited containments such as mud and ice. The outside diameter of the wiper incorporates a crush lip to provide an interference fit with the housing and a face bead to ensure that the crush lip is not trapped in the corner of the housing. These features help prevent contamination from entering the groove. The molded ribs on the internal diameter provide extra stability to the wiper and help prevent the possibility of blow-out due to pressure trapping between the wiper and the main rod seal.The standard Hallite 520 is molded in polyurethane for maximum wear resistance and performance. For heavy duty and more complex applications, it is also offered in a wide range of HythaneÂ® polyurethane and polyester materials to provide the best ingression protection. In harsher environments with heavy contamination, the technical team may advise you to use a Hallite 820 wiper for better debris ingress protection. | O17: Hallite Wiper Seal | P17: HalliteÂ® Type 520 | Q17: 41.148 | R17: 50.8 | S17: 4.572 | T17: 3.44 | U17: =T17-L17 -> -1.04 | V17: 421.4 | W17: 421.4 | X17: 99 | Y17: inch→mm | Z17: 335.4 | AA17: 390 | AB17: ID diff=0.85mm, OD diff=0.80mm [inch→mm]
A18: 108698 | B18: DS011-F-0450-0530-0507 | C18: Dust Seal | D18: 011 | E18: Standard (NBR/PU) | F18: 45 | G18: 53 | H18: 5.0-7.0 | I18: 91 | J18: =I18*0.0087 -> 0.7917 | K18: =ROUND(J18*1.5,2) -> 1.19 | L18: =K18*4 -> 4.76 | M18: WR45-53-5-7M-P-H38 | N18: The Hallite 38 single-lipped wiper/scraper is designed to fit metric housingsÂ including those of ISO 6195A. The proportions of the wiping lip ensure that contactÂ is maintained with the surface of the rod to remove heavily deposited containments such as mud and ice. The outside diameter of the wiper incorporates a crush lip to provide an interference fit with the housing. This feature help prevent contamination from entering the groove. The Hallite 38 is molded in a polyester-based material to provide a tough, abrasion_x0002_resistant wiper for the difficult conditions usually found in mining or earth moving applications. The complete range can be used with a split housing, and the majority can be installed in a blind housing with care | O18: Hallite Wiper Seal | P18: HalliteÂ® Type 38 | Q18: 45 | R18: 53 | S18: 5 | T18: 7.1 | U18: =T18-L18 -> 2.34 | V18: 869.75 | W18: 869.75 | X18: 124 | Y18: mm | Z18: 778.75 | AA18: 855.8 | AB18: ID diff=0.00mm, OD diff=0.00mm
A19: 108697 | B19: DS011-F-0450-0550-0507 | C19: Dust Seal | D19: 011 | E19: Standard (NBR/PU) | F19: 45 | G19: 55 | H19: 5.0-7.0 | I19: 104 | J19: =I19*0.0087 -> 0.9048 | K19: =ROUND(J19*1.5,2) -> 1.36 | L19: =K19*4 -> 5.44 | M19: WR45-55-5-7M-P-H38 | N19: The Hallite 38 single-lipped wiper/scraper is designed to fit metric housingsÂ including those of ISO 6195A. The proportions of the wiping lip ensure that contactÂ is maintained with the surface of the rod to remove heavily deposited containments such as mud and ice. The outside diameter of the wiper incorporates a crush lip to provide an interference fit with the housing. This feature help prevent contamination from entering the groove. The Hallite 38 is molded in a polyester-based material to provide a tough, abrasion_x0002_resistant wiper for the difficult conditions usually found in mining or earth moving applications. The complete range can be used with a split housing, and the majority can be installed in a blind housing with care | O19: Hallite Wiper Seal | P19: HalliteÂ® Type 38 | Q19: 45 | R19: 55 | S19: 5 | T19: 10.53 | U19: =T19-L19 -> 5.09 | V19: 1289.92 | W19: 1289.92 | X19: 89 | Y19: mm | Z19: 1185.92 | AA19: 1140.3 | AB19: ID diff=0.00mm, OD diff=0.00mm
A20: 108699 | B20: DS011-F-0500-0580-0507 | C20: Dust Seal | D20: 011 | E20: Standard (NBR/PU) | F20: 50 | G20: 58 | H20: 5.0-7.0 | I20: 94 | J20: =I20*0.0087 -> 0.8178 | K20: =ROUND(J20*1.5,2) -> 1.23 | L20: =K20*4 -> 4.92 | M20: WR50-58-5-7M-R-H33 | N20: The Hallite 33 wiper has a lip designed to remove lightly adhered dirt from the rod i.e. mud, dust or moisture.Â The wiper is manufactured from a hard nitrile rubber suitable for installing in a grooved housing. Rod diameters(Ã˜d1) of 20mm and below require a two piece housing .Â To prevent dirt passing the outside of the wiper and to reduce the pumping action, the outside diameter is anÂ interference fit with the housing. Certain sizes of the standard Hallite 33 metric range are suitable for ISO 6195Â Housing Type A.Â It should also be noted that the Hallite 33 inch profile differs from the metric profile | O20: Hallite Wiper Seal | P20: HalliteÂ® Type 33 | Q20: 50 | R20: 58 | S20: 5 | T20: 10.98 | U20: =T20-L20 -> 6.06 | V20: 1345.05 | W20: 1345.05 | X20: 81 | Y20: mm | Z20: 1251.05 | AA20: 1330.9 | AB20: ID diff=0.00mm, OD diff=0.00mm
A21: 110068 | B21: DS011-F-0500-0600-0308 | C21: Dust Seal | D21: 011 | E21: Standard (NBR/PU) | F21: 50 | G21: 60 | H21: 3.0-8.0 | I21: 119 | J21: =I21*0.0087 -> 1.0353 | K21: =ROUND(J21*1.5,2) -> 1.55 | L21: =K21*4 -> 6.2 | M21: WR50-60-5-7M-P-H38 | N21: The Hallite 38 single-lipped wiper/scraper is designed to fit metric housingsÂ including those of ISO 6195A. The proportions of the wiping lip ensure that contactÂ is maintained with the surface of the rod to remove heavily deposited containments such as mud and ice. The outside diameter of the wiper incorporates a crush lip to provide an interference fit with the housing. This feature help prevent contamination from entering the groove. The Hallite 38 is molded in a polyester-based material to provide a tough, abrasion_x0002_resistant wiper for the difficult conditions usually found in mining or earth moving applications. The complete range can be used with a split housing, and the majority can be installed in a blind housing with care | O21: Hallite Wiper Seal | P21: HalliteÂ® Type 38 | Q21: 50 | R21: 60 | S21: 5 | T21: 8.36 | U21: =T21-L21 -> 2.16 | V21: 1024.1 | W21: 1024.1 | X21: 83 | Y21: mm | Z21: 905.1 | AA21: 760.6 | AB21: ID diff=0.00mm, OD diff=0.00mm
... A31: 108707 | B31: DS011-F-0750-0870-0712 | C31: Dust Seal | D31: 011 | E31: Standard (NBR/PU) | F31: 75 | G31: 87 | H31: 7.0-12.0 | I31: 259 | J31: =I31*0.0087 -> 2.2533 | K31: =ROUND(J31*1.5,2) -> 3.38 | L31: =K31*4 -> 13.52 | M31: WR75-87-6-9M-R-H33 | N31: The Hallite 33 wiper has a lip designed to remove lightly adhered dirt from the rod i.e. mud, dust or moisture.Â The wiper is manufactured from a hard nitrile rubber suitable for installing in a grooved housing. Rod diameters(Ã˜d1) of 20mm and below require a two piece housing .Â To prevent dirt passing the outside of the wiper and to reduce the pumping action, the outside diameter is anÂ interference fit with the housing. Certain sizes of the standard Hallite 33 metric range are suitable for ISO 6195Â Housing Type A.Â It should also be noted that the Hallite 33 inch profile differs from the metric profile | O31: Hallite Wiper Seal | P31: HalliteÂ® Type 33 | Q31: 75 | R31: 87 | S31: 6 | T31: 15.46 | U31: =T31-L31 -> 1.94 | V31: 1893.85 | W31: 1893.85 | X31: 18 | Y31: mm | Z31: 1634.85 | AA31: 631.2 | AB31: ID diff=0.00mm, OD diff=0.00mm
A32: 108708 | B32: DS011-F-0800-0920-0712 | C32: Dust Seal | D32: 011 | E32: Standard (NBR/PU) | F32: 80 | G32: 92 | H32: 7.0-12.0 | I32: 276 | J32: =I32*0.0087 -> 2.4012 | K32: =ROUND(J32*1.5,2) -> 3.6 | L32: =K32*4 -> 14.4 | M32: WR80-92-7.2-12M-P-H38 | N32: The Hallite 38 single-lipped wiper/scraper is designed to fit metric housingsÂ including those of ISO 6195A. The proportions of the wiping lip ensure that contactÂ is maintained with the surface of the rod to remove heavily deposited containments such as mud and ice. The outside diameter of the wiper incorporates a crush lip to provide an interference fit with the housing. This feature help prevent contamination from entering the groove. The Hallite 38 is molded in a polyester-based material to provide a tough, abrasion_x0002_resistant wiper for the difficult conditions usually found in mining or earth moving applications. The complete range can be used with a split housing, and the majority can be installed in a blind housing with care | O32: Hallite Wiper Seal | P32: HalliteÂ® Type 38 | Q32: 80 | R32: 92 | S32: 7.2 | T32: 21.06 | U32: =T32-L32 -> 6.66 | V32: 2579.85 | W32: 2579.85 | X32: Get A Quote | Y32: mm | Z32: 2303.85 | AA32: 834.7 | AB32: ID diff=0.00mm, OD diff=0.00mm
A33: 108709 | B33: DS011-F-0850-0970-0712 | C33: Dust Seal | D33: 011 | E33: Standard (NBR/PU) | F33: 85 | G33: 97 | H33: 7.0-12.0 | I33: 293 | J33: =I33*0.0087 -> 2.5491 | K33: =ROUND(J33*1.5,2) -> 3.82 | L33: =K33*4 -> 15.28 | M33: WR85-97-8-12A6-P-H842 | N33: The Hallite 842 single-lipped, snap-in rod wiper is developed specifically for use in harsher environments with heavy contamination, such as in agriculture, off-highway, forestry, and long wall mining equipment.The unique feature of the Hallite 842 is the Umbrella Wiper Technologyâ„¢, which is a protective debris guard flap on the wiping lip that entirely covers the gland housing and prevents the water/slurry trap that is common with conventional wipers. This feature offers added protection to the integrity of the hydraulic system, providing increased system life by reducing corrosion and preventing the ingress of contamination into the wiper housing groove and hydraulic cylinder gland.The moulded ribs on the internal diameter provide extra stability to the wiper and help prevent the possibility of blow-out due to pressure trapping between the wiper and the main rod seal. | O33: Hallite Wiper Seal | P33: HalliteÂ® Type 842 | Q33: 85 | R33: 97 | S33: 8 | T33: 27.43 | U33: =T33-L33 -> 12.15 | V33: 3360.18 | W33: 3360.18 | X33: 5 | Y33: mm | Z33: 3067.18 | AA33: 1046.8 | AB33: ID diff=0.00mm, OD diff=0.00mm
A34: 108710 | B34: DS011-F-0900-1020-0712 | C34: Dust Seal | D34: 011 | E34: Standard (NBR/PU) | F34: 90 | G34: 102 | H34: 7.0-12.0 | I34: 301 | J34: =I34*0.0087 -> 2.6187 | K34: =ROUND(J34*1.5,2) -> 3.93 | L34: =K34*4 -> 15.72 | M34: WR90-102-7-12M-P-H38 | N34: The Hallite 38 single-lipped wiper/scraper is designed to fit metric housingsÂ including those of ISO 6195A. The proportions of the wiping lip ensure that contactÂ is maintained with the surface of the rod to remove heavily deposited containments such as mud and ice. The outside diameter of the wiper incorporates a crush lip to provide an interference fit with the housing. This feature help prevent contamination from entering the groove. The Hallite 38 is molded in a polyester-based material to provide a tough, abrasion_x0002_resistant wiper for the difficult conditions usually found in mining or earth moving applications. The complete range can be used with a split housing, and the majority can be installed in a blind housing with care | O34: Hallite Wiper Seal | P34: HalliteÂ® Type 38 | Q34: 90 | R34: 102 | S34: 7 | T34: 12.47 | U34: =T34-L34 -> -3.25 | V34: 1527.58 | W34: 1527.58 | X34: 143 | Y34: mm | Z34: 1226.58 | AA34: 407.5 | AB34: ID diff=0.00mm, OD diff=0.00mm
A35: 109128 | B35: DS011-F-0950-1070-0712 | C35: Dust Seal | D35: 011 | E35: Standard (NBR/PU) | F35: 95 | G35: 107 | H35: 7.0-12.0 | I35: 318 | J35: =I35*0.0087 -> 2.7666 | K35: =ROUND(J35*1.5,2) -> 4.15 | L35: =K35*4 -> 16.6 | M35: WR95-107-7-12M-P-H38 | N35: The Hallite 38 single-lipped wiper/scraper is designed to fit metric housingsÂ including those of ISO 6195A. The proportions of the wiping lip ensure that contactÂ is maintained with the surface of the rod to remove heavily deposited containments such as mud and ice. The outside diameter of the wiper incorporates a crush lip to provide an interference fit with the housing. This feature help prevent contamination from entering the groove. The Hallite 38 is molded in a polyester-based material to provide a tough, abrasion_x0002_resistant wiper for the difficult conditions usually found in mining or earth moving applications. The complete range can be used with a split housing, and the majority can be installed in a blind housing with care | O35: Hallite Wiper Seal | P35: HalliteÂ® Type 38 | Q35: 95 | R35: 107 | S35: 7 | T35: 22.9 | U35: =T35-L35 -> 6.3 | V35: 2805.25 | W35: 2805.25 | X35: 31 | Y35: mm | Z35: 2487.25 | AA35: 782.2 | AB35: ID diff=0.00mm, OD diff=0.00mm
A36: 108711 | B36: DS011-F-1000-1120-0712 | C36: Dust Seal | D36: 011 | E36: Standard (NBR/PU) | F36: 100 | G36: 112 | H36: 7.0-12.0 | I36: 326 | J36: =I36*0.0087 -> 2.8362 | K36: =ROUND(J36*1.5,2) -> 4.25 | L36: =K36*4 -> 17 | M36: WR100-112-7.2-12M-P-H38 | N36: The Hallite 38 single-lipped wiper/scraper is designed to fit metric housingsÂ including those of ISO 6195A. The proportions of the wiping lip ensure that contactÂ is maintained with the surface of the rod to remove heavily deposited containments such as mud and ice. The outside diameter of the wiper incorporates a crush lip to provide an interference fit with the housing. This feature help prevent contamination from entering the groove. The Hallite 38 is molded in a polyester-based material to provide a tough, abrasion_x0002_resistant wiper for the difficult conditions usually found in mining or earth moving applications. The complete range can be used with a split housing, and the majority can be installed in a blind housing with care | O36: Hallite Wiper Seal | P36: HalliteÂ® Type 38 | Q36: 100 | R36: 112 | S36: 7.2 | T36: 24.31 | U36: =T36-L36 -> 7.31 | V36: 2977.98 | W36: 2977.98 | X36: 131 | Y36: mm | Z36: 2651.98 | AA36: 813.5 | AB36: ID diff=0.00mm, OD diff=0.00mm
A37: 108713 | B37: DS011-F-1100-1220-0712 | C37: Dust Seal | D37: 011 | E37: Standard (NBR/PU) | F37: 110 | G37: 122 | H37: 7.0-12.0 | I37: 367 | J37: =I37*0.0087 -> 3.1929 | K37: =ROUND(J37*1.5,2) -> 4.79 | L37: =K37*4 -> 19.16 | M37: WR110-122-7.2-12M-P-H38 | N37: The Hallite 38 single-lipped wiper/scraper is designed to fit metric housingsÂ including those of ISO 6195A. The proportions of the wiping lip ensure that contactÂ is maintained with the surface of the rod to remove heavily deposited containments such as mud and ice. The outside diameter of the wiper incorporates a crush lip to provide an interference fit with the housing. This feature help prevent contamination from entering the groove. The Hallite 38 is molded in a polyester-based material to provide a tough, abrasion_x0002_resistant wiper for the difficult conditions usually found in mining or earth moving applications. The complete range can be used with a split housing, and the majority can be installed in a blind housing with care | O37: Hallite Wiper Seal | P37: HalliteÂ® Type 38 | Q37: 110 | R37: 122 | S37: 7.2 | T37: 14.89 | U37: =T37-L37 -> -4.27 | V37: 1824.02 | W37: 1824.02 | X37: 8 | Y37: mm | Z37: 1457.02 | AA37: 397 | AB37: ID diff=0.00mm, OD diff=0.00mm
A38: 109127 | B38: DS011-F-1200-1320-0712 | C38: Dust Seal | D38: 011 | E38: Standard (NBR/PU) | F38: 120 | G38: 132 | H38: 7.0-12.0 | I38: 384 | J38: =I38*0.0087 -> 3.3408 | K38: =ROUND(J38*1.5,2) -> 5.01 | L38: =K38*4 -> 20.04 | M38: WR120-132-7-12M-P-H38 | N38: The Hallite 38 single-lipped wiper/scraper is designed to fit metric housingsÂ including those of ISO 6195A. The proportions of the wiping lip ensure that contactÂ is maintained with the surface of the rod to remove heavily deposited containments such as mud and ice. The outside diameter of the wiper incorporates a crush lip to provide an interference fit with the housing. This feature help prevent contamination from entering the groove. The Hallite 38 is molded in a polyester-based material to provide a tough, abrasion_x0002_resistant wiper for the difficult conditions usually found in mining or earth moving applications. The complete range can be used with a split housing, and the majority can be installed in a blind housing with care | O38: Hallite Wiper Seal | P38: HalliteÂ® Type 38 | Q38: 120 | R38: 132 | S38: 7 | T38: 34.64 | U38: =T38-L38 -> 14.6 | V38: 4243.4 | W38: 4243.4 | X38: 47 | Y38: mm | Z38: 3859.4 | AA38: 1005.1 | AB38: ID diff=0.00mm, OD diff=0.00mm
A39: 108716 | B39: DS011-F-1250-1370-0712 | C39: Dust Seal | D39: 011 | E39: Standard (NBR/PU) | F39: 125 | G39: 137 | H39: 7.0-12.0 | I39: 401 | J39: =I39*0.0087 -> 3.4887 | K39: =ROUND(J39*1.5,2) -> 5.23 | L39: =K39*4 -> 20.92 | M39: WR125-137-7.7-12M-P-H38 | N39: The Hallite 38 single-lipped wiper/scraper is designed to fit metric housingsÂ including those of ISO 6195A. The proportions of the wiping lip ensure that contactÂ is maintained with the surface of the rod to remove heavily deposited containments such as mud and ice. The outside diameter of the wiper incorporates a crush lip to provide an interference fit with the housing. This feature help prevent contamination from entering the groove. The Hallite 38 is molded in a polyester-based material to provide a tough, abrasion_x0002_resistant wiper for the difficult conditions usually found in mining or earth moving applications. The complete range can be used with a split housing, and the majority can be installed in a blind housing with care | O39: Hallite Wiper Seal | P39: HalliteÂ® Type 38 | Q39: 125 | R39: 137 | S39: 7.7 | T39: 35.78 | U39: =T39-L39 -> 14.86 | V39: 4383.05 | W39: 4383.05 | X39: 72 | Y39: mm | Z39: 3982.05 | AA39: 993 | AB39: ID diff=0.00mm, OD diff=0.00mm
A40: 113216 | B40: DS011-F-1250-1400-1016 | C40: Dust Seal | D40: 011 | E40: Standard (NBR/PU) | F40: 125 | G40: 140 | H40: 10.0-16.0 | I40: 634 | J40: =I40*0.0087 -> 5.5158 | K40: =ROUND(J40*1.5,2) -> 8.27 | L40: =K40*4 -> 33.08 | M40: WR125-140-9.5-14M-P-H38 | N40: The Hallite 38 single-lipped wiper/scraper is designed to fit metric housingsÂ including those of ISO 6195A. The proportions of the wiping lip ensure that contactÂ is maintained with the surface of the rod to remove heavily deposited containments such as mud and ice. The outside diameter of the wiper incorporates a crush lip to provide an interference fit with the housing. This feature help prevent contamination from entering the groove. The Hallite 38 is molded in a polyester-based material to provide a tough, abrasion_x0002_resistant wiper for the difficult conditions usually found in mining or earth moving applications. The complete range can be used with a split housing, and the majority can be installed in a blind housing with care | O40: Hallite Wiper Seal | P40: HalliteÂ® Type 38 | Q40: 125 | R40: 140 | S40: 9.5 | T40: 18.98 | U40: =T40-L40 -> -14.1 | V40: 2325.05 | W40: 2325.05 | X40: 213 | Y40: mm | Z40: 1691.05 | AA40: 266.7 | AB40: ID diff=0.00mm, OD diff=0.00mm
A41: 108717 | B41: DS011-F-1300-1420-0712 | C41: Dust Seal | D41: 011 | E41: Standard (NBR/PU) | F41: 130 | G41: 142 | H41: 7.0-12.0 | I41: 426 | J41: =I41*0.0087 -> 3.7062 | K41: =ROUND(J41*1.5,2) -> 5.56 | L41: =K41*4 -> 22.24 | M41: WR130-142-7.2-12M-P-H38 | N41: The Hallite 38 single-lipped wiper/scraper is designed to fit metric housingsÂ including those of ISO 6195A. The proportions of the wiping lip ensure that contactÂ is maintained with the surface of the rod to remove heavily deposited containments such as mud and ice. The outside diameter of the wiper incorporates a crush lip to provide an interference fit with the housing. This feature help prevent contamination from entering the groove. The Hallite 38 is molded in a polyester-based material to provide a tough, abrasion_x0002_resistant wiper for the difficult conditions usually found in mining or earth moving applications. The complete range can be used with a split housing, and the majority can be installed in a blind housing with care | O41: Hallite Wiper Seal | P41: HalliteÂ® Type 38 | Q41: 130 | R41: 142 | S41: 7.2 | T41: 17.97 | U41: =T41-L41 -> -4.27 | V41: 2201.32 | W41: 2201.32 | X41: 26 | Y41: mm | Z41: 1775.32 | AA41: 416.7 | AB41: ID diff=0.00mm, OD diff=0.00mm
A42: 108719 | B42: DS011-F-1400-1520-0712 | C42: Dust Seal | D42: 011 | E42: Standard (NBR/PU) | F42: 140 | G42: 152 | H42: 7.0-12.0 | I42: 443 | J42: =I42*0.0087 -> 3.8541 | K42: =ROUND(J42*1.5,2) -> 5.78 | L42: =K42*4 -> 23.12 | M42: WR140-152-7.7-12M-P-H38 | N42: The Hallite 38 single-lipped wiper/scraper is designed to fit metric housingsÂ including those of ISO 6195A. The proportions of the wiping lip ensure that contactÂ is maintained with the surface of the rod to remove heavily deposited containments such as mud and ice. The outside diameter of the wiper incorporates a crush lip to provide an interference fit with the housing. This feature help prevent contamination from entering the groove. The Hallite 38 is molded in a polyester-based material to provide a tough, abrasion_x0002_resistant wiper for the difficult conditions usually found in mining or earth moving applications. The complete range can be used with a split housing, and the majority can be installed in a blind housing with care | O42: Hallite Wiper Seal | P42: HalliteÂ® Type 38 | Q42: 140 | R42: 152 | S42: 7.7 | T42: 41.68 | U42: =T42-L42 -> 18.56 | V42: 5105.8 | W42: 5105.8 | X42: 5 | Y42: mm | Z42: 4662.8 | AA42: 1052.6 | AB42: ID diff=0.00mm, OD diff=0.00mm
A43: 108720 | B43: DS011-F-1400-1550-1016 | C43: Dust Seal | D43: 011 | E43: Standard (NBR/PU) | F43: 140 | G43: 155 | H43: 10.0-16.0 | I43: 700 | J43: =I43*0.0087 -> 6.09 | K43: =ROUND(J43*1.5,2) -> 9.14 | L43: =K43*4 -> 36.56 | M43: WR140-155-9.5-12.5M-R-H33 | N43: The Hallite 33 wiper has a lip designed to remove lightly adhered dirt from the rod i.e. mud, dust or moisture.Â The wiper is manufactured from a hard nitrile rubber suitable for installing in a grooved housing. Rod diameters(Ã˜d1) of 20mm and below require a two piece housing .Â To prevent dirt passing the outside of the wiper and to reduce the pumping action, the outside diameter is anÂ interference fit with the housing. Certain sizes of the standard Hallite 33 metric range are suitable for ISO 6195Â Housing Type A.Â It should also be noted that the Hallite 33 inch profile differs from the metric profile | O43: Hallite Wiper Seal | P43: HalliteÂ® Type 33 | Q43: 140 | R43: 155 | S43: 9.5 | T43: 33.6 | U43: =T43-L43 -> -2.96 | V43: 4116 | W43: 4116 | X43: 6 | Y43: mm | Z43: 3416 | AA43: 488 | AB43: ID diff=0.00mm, OD diff=0.00mm
A44: 108721 | B44: DS011-F-1500-1620-0712 | C44: Dust Seal | D44: 011 | E44: Standard (NBR/PU) | F44: 150 | G44: 162 | H44: 7.0-12.0 | I44: 476 | J44: =I44*0.0087 -> 4.1412 | K44: =ROUND(J44*1.5,2) -> 6.21 | L44: =K44*4 -> 24.84 | M44: WR150-162-7-12M-P-H38 | N44: The Hallite 38 single-lipped wiper/scraper is designed to fit metric housingsÂ including those of ISO 6195A. The proportions of the wiping lip ensure that contactÂ is maintained with the surface of the rod to remove heavily deposited containments such as mud and ice. The outside diameter of the wiper incorporates a crush lip to provide an interference fit with the housing. This feature help prevent contamination from entering the groove. The Hallite 38 is molded in a polyester-based material to provide a tough, abrasion_x0002_resistant wiper for the difficult conditions usually found in mining or earth moving applications. The complete range can be used with a split housing, and the majority can be installed in a blind housing with care | O44: Hallite Wiper Seal | P44: HalliteÂ® Type 38 | Q44: 150 | R44: 162 | S44: 7 | T44: 23.02 | U44: =T44-L44 -> -1.82 | V44: 2819.95 | W44: 2819.95 | X44: 25 | Y44: mm | Z44: 2343.95 | AA44: 492.4 | AB44: ID diff=0.00mm, OD diff=0.00mm
A45: 108722 | B45: DS011-F-1500-1650-1016 | C45: Dust Seal | D45: 011 | E45: Standard (NBR/PU) | F45: 150 | G45: 165 | H45: 10.0-16.0 | I45: 742 | J45: =I45*0.0087 -> 6.4554 | K45: =ROUND(J45*1.5,2) -> 9.68 | L45: =K45*4 -> 38.72 | M45: WR150-165-7.2-12M-P-H38 | N45: The Hallite 38 single-lipped wiper/scraper is designed to fit metric housingsÂ including those of ISO 6195A. The proportions of the wiping lip ensure that contactÂ is maintained with the surface of the rod to remove heavily deposited containments such as mud and ice. The outside diameter of the wiper incorporates a crush lip to provide an interference fit with the housing. This feature help prevent contamination from entering the groove. The Hallite 38 is molded in a polyester-based material to provide a tough, abrasion_x0002_resistant wiper for the difficult conditions usually found in mining or earth moving applications. The complete range can be used with a split housing, and the majority can be installed in a blind housing with care | O45: Hallite Wiper Seal | P45: HalliteÂ® Type 38 | Q45: 150 | R45: 165 | S45: 7.2 | T45: 22.46 | U45: =T45-L45 -> -16.26 | V45: 2751.35 | W45: 2751.35 | X45: Get A Quote | Y45: mm | Z45: 2009.35 | AA45: 270.8 | AB45: ID diff=0.00mm, OD diff=0.00mm
A46: 108725 | B46: DS011-F-1600-1750-1016 | C46: Dust Seal | D46: 011 | E46: Standard (NBR/PU) | F46: 160 | G46: 175 | H46: 10.0-16.0 | I46: 793 | J46: =I46*0.0087 -> 6.8991 | K46: =ROUND(J46*1.5,2) -> 10.35 | L46: =K46*4 -> 41.4 | M46: WR160-175-9.5-14M-P-H38 | N46: The Hallite 38 single-lipped wiper/scraper is designed to fit metric housingsÂ including those of ISO 6195A. The proportions of the wiping lip ensure that contactÂ is maintained with the surface of the rod to remove heavily deposited containments such as mud and ice. The outside diameter of the wiper incorporates a crush lip to provide an interference fit with the housing. This feature help prevent contamination from entering the groove. The Hallite 38 is molded in a polyester-based material to provide a tough, abrasion_x0002_resistant wiper for the difficult conditions usually found in mining or earth moving applications. The complete range can be used with a split housing, and the majority can be installed in a blind housing with care | O46: Hallite Wiper Seal | P46: HalliteÂ® Type 38 | Q46: 160 | R46: 175 | S46: 9.5 | T46: 24.53 | U46: =T46-L46 -> -16.87 | V46: 3004.92 | W46: 3004.92 | X46: 154 | Y46: mm | Z46: 2211.92 | AA46: 278.9 | AB46: ID diff=0.00mm, OD diff=0.00mm
A47: 106771 | B47: DS011-N-0120-0180-03.8/5 | C47: Dust Seal | D47: 011 | E47: NBR | F47: 12 | G47: 18 | H47: 3.8-5.0 | I47: 25 | J47: =I47*0.0087 -> 0.2175 | K47: =ROUND(J47*1.5,2) -> 0.33 | L47: =K47*4 -> 1.32 | M47: WR12-18-4-7UL-P-H839 | N47: The Hallite 839 double-lipped, snap-in wiper is designed to fit standard housings, including many ISO 6195C sizes, and to exclude dirt and moisture from entering the cylinder. The design minimises the oil transfer out of the ram on the cylinder rod by collecting traces of fluid passing the rod seal.Opposite the wiper lip are two sealing lips that are precision trimmed at an angle to give optimal rod sealing performance. The Hallite 839 is designed to have an interference in the seal housing groove to improve the stability of the wiper in the gland and to reduce the possibility of ingress around the outside of the wiper.Hallite recommends a vent is provided between the seal and the wiper to avoid a pressure trap. For customers that require a wiper for heavier duty applications, the Hallite technical team may advise you to use a Hallite 844 wiper instead of the Hallite 839. Contact your local Hallite team for more information. | O47: Hallite Wiper Seal | P47: HalliteÂ® Type 839 | Q47: 12 | R47: 18 | S47: 4 | T47: 4.28 | U47: =T47-L47 -> 2.96 | V47: 524.3 | W47: 524.3 | X47: 20 | Y47: mm | Z47: 499.3 | AA47: 1997.2 | AB47: ID diff=0.00mm, OD diff=0.00mm
A48: 113057 | B48: DS011-N-0120-0200-0507 | C48: Dust Seal | D48: 011 | E48: NBR | F48: 12 | G48: 20 | H48: 5.0-7.0 | I48: 29 | J48: =I48*0.0087 -> 0.2523 | K48: =ROUND(J48*1.5,2) -> 0.38 | L48: =K48*4 -> 1.52 | M48: WR12-20-4-6M-R-H33 | N48: The Hallite 33 wiper has a lip designed to remove lightly adhered dirt from the rod i.e. mud, dust or moisture.Â The wiper is manufactured from a hard nitrile rubber suitable for installing in a grooved housing. Rod diameters(Ã˜d1) of 20mm and below require a two piece housing .Â To prevent dirt passing the outside of the wiper and to reduce the pumping action, the outside diameter is anÂ interference fit with the housing. Certain sizes of the standard Hallite 33 metric range are suitable for ISO 6195Â Housing Type A.Â It should also be noted that the Hallite 33 inch profile differs from the metric profile | O48: Hallite Wiper Seal | P48: HalliteÂ® Type 33 | Q48: 12 | R48: 20 | S48: 4 | T48: 11.23 | U48: =T48-L48 -> 9.71 | V48: 1375.68 | W48: 1375.68 | X48: 24 | Y48: mm | Z48: 1346.68 | AA48: 4643.7 | AB48: ID diff=0.00mm, OD diff=0.00mm
A49: 179329 | B49: DS011-N-0150-0216-03.8/5.3 | C49: Dust Seal | D49: 011 | E49: NBR | F49: 15 | G49: 21.6 | H49: 3.8-5.3 | I49: 27 | J49: =I49*0.0087 -> 0.2349 | K49: =ROUND(J49*1.5,2) -> 0.35 | L49: =K49*4 -> 1.4 | M49: WR14-22-4-6M-R-H33 | N49: The Hallite 33 wiper has a lip designed to remove lightly adhered dirt from the rod i.e. mud, dust or moisture.Â The wiper is manufactured from a hard nitrile rubber suitable for installing in a grooved housing. Rod diameters(Ã˜d1) of 20mm and below require a two piece housing .Â To prevent dirt passing the outside of the wiper and to reduce the pumping action, the outside diameter is anÂ interference fit with the housing. Certain sizes of the standard Hallite 33 metric range are suitable for ISO 6195Â Housing Type A.Â It should also be noted that the Hallite 33 inch profile differs from the metric profile | O49: Hallite Wiper Seal | P49: HalliteÂ® Type 33 | Q49: 14 | R49: 22 | S49: 4 | T49: 9.43 | U49: =T49-L49 -> 8.03 | V49: 1155.18 | W49: 1155.18 | X49: 7 | Y49: mm | Z49: 1128.18 | AA49: 4178.4 | AB49: ID diff=1.00mm, OD diff=0.40mm
...

Sheet SKU Mapping
A1: SKU to Part Number Mapping
A3: Metric | B3: Value | D3: Recommended mapping rule | E3: Use Column M SKU as the lookup key and return all matching Column B part numbers.
A4: Source rows checked | B4: 2638 | D4: Important finding | E4: SKU is not always unique to one internal part number. Review Mapping Type = 1:Many.
A5: Unique SKUs | B5: 1532 | D5: Suggested Excel lookup | E5: {=_xlfn.TEXTJOIN(" | ",TRUE,_xlfn._xlws.FILTER(PriceList!$B$4:$B$2641,PriceList!$M$4:$M$2641=A12))} -> #VALUE!
A6: Blank part numbers in Column B | B6: 0 | D6: Source range | E6: PriceList!B4:M2641
A7: Blank SKUs in Column M | B7: 0
A8: Column B values still containing X | B8: 0
A9: Column M values containing X | B9: 45
A10: Unique SKUs mapping 1:1 | B10: 836
A11: Unique SKUs mapping 1:Many | B11: 696
A12: SKU | B12: Matching Part Count | C12: Mapping Type | D12: Mapped Part Number(s) | E12: Source Row(s) | F12: FPE Dimensions | G12: Sample Product Type
A13: AIRZET25-17-3-V | B13: =COUNTIF(PriceList!$M$4:$M$2641,A13) -> 1 | C13: =IF(B13=1,"1:1","1:Many") -> 1:1 | D13: {=_xlfn.TEXTJOIN(" | ",TRUE,_xlfn._xlws.FILTER(PriceList!$B$4:$B$2641,PriceList!$M$4:$M$2641=A13,""))} -> PNRS010-0160-0260-105 | E13: {=_xlfn.TEXTJOIN(", ",TRUE,_xlfn._xlws.FILTER(ROW(PriceList!$B$4:$B$2641),PriceList!$M$4:$M$2641=A13,""))} -> 2152 | F13: {=_xlfn.TEXTJOIN(" | ",TRUE,_xlfn.UNIQUE(_xlfn._xlws.FILTER(PriceList!$Q$4:$Q$2641&" x "&PriceList!$R$4:$R$2641&" x "&PriceList!$S$4:$S$2641,PriceList!$M$4:$M$2641=A13,"")))} -> 17 x 25 x 3 | G13: {=INDEX(_xlfn._xlws.FILTER(PriceList!$P$4:$P$2641,PriceList!$M$4:$M$2641=A13,""),1)} -> Piston Seal - Pneumatic - Airzet Type
A14: AIRZET28-19-2.5-R | B14: =COUNTIF(PriceList!$M$4:$M$2641,A14) -> 1 | C14: =IF(B14=1,"1:1","1:Many") -> 1:1 | D14: {=_xlfn.TEXTJOIN(" | ",TRUE,_xlfn._xlws.FILTER(PriceList!$B$4:$B$2641,PriceList!$M$4:$M$2641=A14,""))} -> PNRS010-0180-0280-105 | E14: {=_xlfn.TEXTJOIN(", ",TRUE,_xlfn._xlws.FILTER(ROW(PriceList!$B$4:$B$2641),PriceList!$M$4:$M$2641=A14,""))} -> 2153 | F14: {=_xlfn.TEXTJOIN(" | ",TRUE,_xlfn.UNIQUE(_xlfn._xlws.FILTER(PriceList!$Q$4:$Q$2641&" x "&PriceList!$R$4:$R$2641&" x "&PriceList!$S$4:$S$2641,PriceList!$M$4:$M$2641=A14,"")))} -> 19 x 28 x 2.5 | G14: {=INDEX(_xlfn._xlws.FILTER(PriceList!$P$4:$P$2641,PriceList!$M$4:$M$2641=A14,""),1)} -> Piston Seal - Pneumatic - Airzet Type
A15: AIRZET30-21-2.5-R | B15: =COUNTIF(PriceList!$M$4:$M$2641,A15) -> 1 | C15: =IF(B15=1,"1:1","1:Many") -> 1:1 | D15: {=_xlfn.TEXTJOIN(" | ",TRUE,_xlfn._xlws.FILTER(PriceList!$B$4:$B$2641,PriceList!$M$4:$M$2641=A15,""))} -> PNRS010-0200-0300-105 | E15: {=_xlfn.TEXTJOIN(", ",TRUE,_xlfn._xlws.FILTER(ROW(PriceList!$B$4:$B$2641),PriceList!$M$4:$M$2641=A15,""))} -> 2154 | F15: {=_xlfn.TEXTJOIN(" | ",TRUE,_xlfn.UNIQUE(_xlfn._xlws.FILTER(PriceList!$Q$4:$Q$2641&" x "&PriceList!$R$4:$R$2641&" x "&PriceList!$S$4:$S$2641,PriceList!$M$4:$M$2641=A15,"")))} -> 21 x 30 x 2.5 | G15: {=INDEX(_xlfn._xlws.FILTER(PriceList!$P$4:$P$2641,PriceList!$M$4:$M$2641=A15,""),1)} -> Piston Seal - Pneumatic - Airzet Type
A16: AIRZET32-23-2.5-R | B16: =COUNTIF(PriceList!$M$4:$M$2641,A16) -> 1 | C16: =IF(B16=1,"1:1","1:Many") -> 1:1 | D16: {=_xlfn.TEXTJOIN(" | ",TRUE,_xlfn._xlws.FILTER(PriceList!$B$4:$B$2641,PriceList!$M$4:$M$2641=A16,""))} -> PNRS010-0220-0320-105 | E16: {=_xlfn.TEXTJOIN(", ",TRUE,_xlfn._xlws.FILTER(ROW(PriceList!$B$4:$B$2641),PriceList!$M$4:$M$2641=A16,""))} -> 2155 | F16: {=_xlfn.TEXTJOIN(" | ",TRUE,_xlfn.UNIQUE(_xlfn._xlws.FILTER(PriceList!$Q$4:$Q$2641&" x "&PriceList!$R$4:$R$2641&" x "&PriceList!$S$4:$S$2641,PriceList!$M$4:$M$2641=A16,"")))} -> 23 x 32 x 2.5 | G16: {=INDEX(_xlfn._xlws.FILTER(PriceList!$P$4:$P$2641,PriceList!$M$4:$M$2641=A16,""),1)} -> Piston Seal - Pneumatic - Airzet Type
A17: AIRZET35-26-2.5-R | B17: =COUNTIF(PriceList!$M$4:$M$2641,A17) -> 1 | C17: =IF(B17=1,"1:1","1:Many") -> 1:1 | D17: {=_xlfn.TEXTJOIN(" | ",TRUE,_xlfn._xlws.FILTER(PriceList!$B$4:$B$2641,PriceList!$M$4:$M$2641=A17,""))} -> PNRS010-0250-0350-105 | E17: {=_xlfn.TEXTJOIN(", ",TRUE,_xlfn._xlws.FILTER(ROW(PriceList!$B$4:$B$2641),PriceList!$M$4:$M$2641=A17,""))} -> 2156 | F17: {=_xlfn.TEXTJOIN(" | ",TRUE,_xlfn.UNIQUE(_xlfn._xlws.FILTER(PriceList!$Q$4:$Q$2641&" x "&PriceList!$R$4:$R$2641&" x "&PriceList!$S$4:$S$2641,PriceList!$M$4:$M$2641=A17,"")))} -> 26 x 35 x 2.5 | G17: {=INDEX(_xlfn._xlws.FILTER(PriceList!$P$4:$P$2641,PriceList!$M$4:$M$2641=A17,""),1)} -> Piston Seal - Pneumatic - Airzet Type
A18: AIRZET45-36-2.7-R-K54 | B18: =COUNTIF(PriceList!$M$4:$M$2641,A18) -> 1 | C18: =IF(B18=1,"1:1","1:Many") -> 1:1 | D18: {=_xlfn.TEXTJOIN(" | ",TRUE,_xlfn._xlws.FILTER(PriceList!$B$4:$B$2641,PriceList!$M$4:$M$2641=A18,""))} -> PNRS010-0350-0450-105 | E18: {=_xlfn.TEXTJOIN(", ",TRUE,_xlfn._xlws.FILTER(ROW(PriceList!$B$4:$B$2641),PriceList!$M$4:$M$2641=A18,""))} -> 2158 | F18: {=_xlfn.TEXTJOIN(" | ",TRUE,_xlfn.UNIQUE(_xlfn._xlws.FILTER(PriceList!$Q$4:$Q$2641&" x "&PriceList!$R$4:$R$2641&" x "&PriceList!$S$4:$S$2641,PriceList!$M$4:$M$2641=A18,"")))} -> 36 x 45 x 2.7 | G18: {=INDEX(_xlfn._xlws.FILTER(PriceList!$P$4:$P$2641,PriceList!$M$4:$M$2641=A18,""),1)} -> Piston Seal - Pneumatic - Airzet Type
A19: AIRZET50-40-3.8-R-K62 | B19: =COUNTIF(PriceList!$M$4:$M$2641,A19) -> 1 | C19: =IF(B19=1,"1:1","1:Many") -> 1:1 | D19: {=_xlfn.TEXTJOIN(" | ",TRUE,_xlfn._xlws.FILTER(PriceList!$B$4:$B$2641,PriceList!$M$4:$M$2641=A19,""))} -> PNRS010-0400-0500-105 | E19: {=_xlfn.TEXTJOIN(", ",TRUE,_xlfn._xlws.FILTER(ROW(PriceList!$B$4:$B$2641),PriceList!$M$4:$M$2641=A19,""))} -> 2159 | F19: {=_xlfn.TEXTJOIN(" | ",TRUE,_xlfn.UNIQUE(_xlfn._xlws.FILTER(PriceList!$Q$4:$Q$2641&" x "&PriceList!$R$4:$R$2641&" x "&PriceList!$S$4:$S$2641,PriceList!$M$4:$M$2641=A19,"")))} -> 40 x 50 x 3.8 | G19: {=INDEX(_xlfn._xlws.FILTER(PriceList!$P$4:$P$2641,PriceList!$M$4:$M$2641=A19,""),1)} -> Piston Seal - Pneumatic - PSD Type
A20: BS006-V75 | B20: =COUNTIF(PriceList!$M$4:$M$2641,A20) -> 1 | C20: =IF(B20=1,"1:1","1:Many") -> 1:1 | D20: {=_xlfn.TEXTJOIN(" | ",TRUE,_xlfn._xlws.FILTER(PriceList!$B$4:$B$2641,PriceList!$M$4:$M$2641=A20,""))} -> ORV8 002.9-1.78 | E20: {=_xlfn.TEXTJOIN(", ",TRUE,_xlfn._xlws.FILTER(ROW(PriceList!$B$4:$B$2641),PriceList!$M$4:$M$2641=A20,""))} -> 1543 | F20: {=_xlfn.TEXTJOIN(" | ",TRUE,_xlfn.UNIQUE(_xlfn._xlws.FILTER(PriceList!$Q$4:$Q$2641&" x "&PriceList!$R$4:$R$2641&" x "&PriceList!$S$4:$S$2641,PriceList!$M$4:$M$2641=A20,"")))} -> 2.794 x 6.35 x 1.778 | G20: {=INDEX(_xlfn._xlws.FILTER(PriceList!$P$4:$P$2641,PriceList!$M$4:$M$2641=A20,""),1)} -> O Ring - FPM/FKM/VitonÂ®
A21: BS007-V75 | B21: =COUNTIF(PriceList!$M$4:$M$2641,A21) -> 1 | C21: =IF(B21=1,"1:1","1:Many") -> 1:1 | D21: {=_xlfn.TEXTJOIN(" | ",TRUE,_xlfn._xlws.FILTER(PriceList!$B$4:$B$2641,PriceList!$M$4:$M$2641=A21,""))} -> ORV8 003.6-1.78 | E21: {=_xlfn.TEXTJOIN(", ",TRUE,_xlfn._xlws.FILTER(ROW(PriceList!$B$4:$B$2641),PriceList!$M$4:$M$2641=A21,""))} -> 1544 | F21: {=_xlfn.TEXTJOIN(" | ",TRUE,_xlfn.UNIQUE(_xlfn._xlws.FILTER(PriceList!$Q$4:$Q$2641&" x "&PriceList!$R$4:$R$2641&" x "&PriceList!$S$4:$S$2641,PriceList!$M$4:$M$2641=A21,"")))} -> 3.556 x 7.112 x 1.778 | G21: {=INDEX(_xlfn._xlws.FILTER(PriceList!$P$4:$P$2641,PriceList!$M$4:$M$2641=A21,""),1)} -> O Ring - FPM/FKM/VitonÂ®
A22: BS009-N70 | B22: =COUNTIF(PriceList!$M$4:$M$2641,A22) -> 1 | C22: =IF(B22=1,"1:1","1:Many") -> 1:1 | D22: {=_xlfn.TEXTJOIN(" | ",TRUE,_xlfn._xlws.FILTER(PriceList!$B$4:$B$2641,PriceList!$M$4:$M$2641=A22,""))} -> OR9N 005.28-1.78 | E22: {=_xlfn.TEXTJOIN(", ",TRUE,_xlfn._xlws.FILTER(ROW(PriceList!$B$4:$B$2641),PriceList!$M$4:$M$2641=A22,""))} -> 932 | F22: {=_xlfn.TEXTJOIN(" | ",TRUE,_xlfn.UNIQUE(_xlfn._xlws.FILTER(PriceList!$Q$4:$Q$2641&" x "&PriceList!$R$4:$R$2641&" x "&PriceList!$S$4:$S$2641,PriceList!$M$4:$M$2641=A22,"")))} -> 5.334 x 8.89 x 1.778 | G22: {=INDEX(_xlfn._xlws.FILTER(PriceList!$P$4:$P$2641,PriceList!$M$4:$M$2641=A22,""),1)} -> O Ring - NBR 70
A23: BS009-V75 | B23: =COUNTIF(PriceList!$M$4:$M$2641,A23) -> 1 | C23: =IF(B23=1,"1:1","1:Many") -> 1:1 | D23: {=_xlfn.TEXTJOIN(" | ",TRUE,_xlfn._xlws.FILTER(PriceList!$B$4:$B$2641,PriceList!$M$4:$M$2641=A23,""))} -> ORV8 005.28-1.78 | E23: {=_xlfn.TEXTJOIN(", ",TRUE,_xlfn._xlws.FILTER(ROW(PriceList!$B$4:$B$2641),PriceList!$M$4:$M$2641=A23,""))} -> 1549 | F23: {=_xlfn.TEXTJOIN(" | ",TRUE,_xlfn.UNIQUE(_xlfn._xlws.FILTER(PriceList!$Q$4:$Q$2641&" x "&PriceList!$R$4:$R$2641&" x "&PriceList!$S$4:$S$2641,PriceList!$M$4:$M$2641=A23,"")))} -> 5.334 x 8.89 x 1.778 | G23: {=INDEX(_xlfn._xlws.FILTER(PriceList!$P$4:$P$2641,PriceList!$M$4:$M$2641=A23,""),1)} -> O Ring - FPM/FKM/VitonÂ®
A24: BS014-V75 | B24: =COUNTIF(PriceList!$M$4:$M$2641,A24) -> 1 | C24: =IF(B24=1,"1:1","1:Many") -> 1:1 | D24: {=_xlfn.TEXTJOIN(" | ",TRUE,_xlfn._xlws.FILTER(PriceList!$B$4:$B$2641,PriceList!$M$4:$M$2641=A24,""))} -> ORV8 012.42-1.78 | E24: {=_xlfn.TEXTJOIN(", ",TRUE,_xlfn._xlws.FILTER(ROW(PriceList!$B$4:$B$2641),PriceList!$M$4:$M$2641=A24,""))} -> 1597 | F24: {=_xlfn.TEXTJOIN(" | ",TRUE,_xlfn.UNIQUE(_xlfn._xlws.FILTER(PriceList!$Q$4:$Q$2641&" x "&PriceList!$R$4:$R$2641&" x "&PriceList!$S$4:$S$2641,PriceList!$M$4:$M$2641=A24,"")))} -> 12.446 x 16.002 x 1.778 | G24: {=INDEX(_xlfn._xlws.FILTER(PriceList!$P$4:$P$2641,PriceList!$M$4:$M$2641=A24,""),1)} -> O Ring - FPM/FKM/VitonÂ®
... A1544: WR96-104-7.6-10M-P-H38 | B1544: =COUNTIF(PriceList!$M$4:$M$2641,A1544) -> 7 | C1544: =IF(B1544=1,"1:1","1:Many") -> 1:Many | D1544: {=_xlfn.TEXTJOIN(" | ",TRUE,_xlfn._xlws.FILTER(PriceList!$B$4:$B$2641,PriceList!$M$4:$M$2641=A1544,""))} -> DS033-U-0950-1050-0710 | DS055-F-0950-1030-0608 | DS055-N-0950-1030-0608 | DS055-U-0950-1030-0608 | DS066-F-0950-1038-060 | DS066-N-0950-1038-060 | DS077-U-0950-1030-0407 | E1544: {=_xlfn.TEXTJOIN(", ",TRUE,_xlfn._xlws.FILTER(ROW(PriceList!$B$4:$B$2641),PriceList!$M$4:$M$2641=A1544,""))} -> 235, 298, 338, 379, 422, 468, 506 | F1544: {=_xlfn.TEXTJOIN(" | ",TRUE,_xlfn.UNIQUE(_xlfn._xlws.FILTER(PriceList!$Q$4:$Q$2641&" x "&PriceList!$R$4:$R$2641&" x "&PriceList!$S$4:$S$2641,PriceList!$M$4:$M$2641=A1544,"")))} -> 96 x 104 x 7.6 | G1544: {=INDEX(_xlfn._xlws.FILTER(PriceList!$P$4:$P$2641,PriceList!$M$4:$M$2641=A1544,""),1)} -> HalliteÂ® Type 38
